## ch9. 예외처리
### `프로그램 오류, 예외 클래스의 계층구조`
#### 1. 예외 클래스의 계층 구조
예외 클래스에는 두가지 종류가 있다. 하나는 `일반 예외`인데 `컴파일러 체크 예외(Checked Exception)`라고도 한다. 컴파일하는 과정에서 예외 처리 코드가 필요한지 검사하기 때문이다. 만약 예외 처리 코드가 없다면 컴파일 오류가 발생한다. 다른 하나는 `실행 예외(Runtime Exception)`이다. 컴파일하는 과정에서 예외 처리 코드를 검사하지 않는 예외를 말한다.

->  컴파일시 예외 처리를 확인하는 차이일 뿐, 두 가지 예외는 모두 예외 처리가 필요하다.

- CheackedException : 명시적으로 예외처리를 강제화 O (컴파일러가 알려줌)
- UncheckerException : 명시적으로 예외처리를 강제화 X

<br>

```
- 모든 객체의 최상위 부모가 Object이듯, 예외도 최상위 부모는 Object
- Throwable : 최상위 예외.
- Error : 메모리 부족이나 심각한 시스템 오류같은 복구 불가능한 예외. 개발자가 잡을 수 없는 예외
- Exception : 컴파일러가 체크하는 checked exception. 단 RuntimeException은 예외.
- RuntimeException : 컴파일러가 체크하지 않는 unchecked exception, 런타임 예외
```

<br>

### `예외 처리 try-catch`
#### 1. try-catch문

< 기본 구조 >
```java
try {
    <수행할 문장 1>;
    <수행할 문장 2>;
    ...
} catch (예외1) {
    <수행할 문장 A>;
    ...
} catch (예외2) {
    <수행할 문장 a>;
    ...
}
```
```java
 try {
    <수행할 문장 1>;
    <수행할 문장 2>;
    ...
} catch (예외1 | 예외2) {  // 둘 중 하나가 예외일 경우 A 수행 (멀티 catch)
    <수행할 문장 A>;
    ...
}
```
첫 번째 코드의 try문 에서 예외가 발생하여 catch 예외1이 수행된다면 그 다음 예외2의 catch문은 수행되지 않는다. 그리고 try문 안의 수행할 문장 중 예외가 발생하지 않는다면 catch문 안의 내용은 수행되지 않는다.

<br>

#### < 다중 catch문 작성시 주의사항 >

다중 catch문을 작성할 때 주의할 점은 상위 예외클래스가 하위 예외 클래스보다 아래쪽에 위치해야한다는 것이다.

<br>

#### 2. finally
어떤 예외가 발생하더라도 반드시 실행되는 부분이 있는데, 바로 finally 구문이다.
```java
public class DivideExceptionSample {
    void finalMessage() {
        System.out.println("그럼 수고하세요.");
    }

    public static void main(String[] args) {
        DivideExceptionSample sample = new DivideExceptionSample();
        int result;
        try {
            result = 5 / 0;
            sample.finalMessage();       // 이 코드는 실행되지 않는다.
        } catch (ArithmeticException e) {
            result = -1;
            System.out.println("숫자는 0으로 나눌 수 없습니다.");
        } finally {
            sample.finalMessage();    // 이곳에서는 예외와 상관없이 무조건 수행된다.
        }
    }
}
```
위 try문에서 sample.finalMessage(); 는 절대로 실행될 수 없습니다. 왜냐하면 result = 5 / 0;가 실행되면서 ArithmeticException이 발생하여 catch 구문으로 예외처리가 넘어가기 때문이다.

만약 result = 5 / 0; 이후에 sample.finalMessage(); 메소드가 반드시 실행되어야 한다면 이런 경우를 처리하기 위해 자바에서는 위와 같이 finally문을 사용한다.

<br>

### `사용자 정의 예외와 예외발생`
프로그램을 개발하다 보면 자바 표준 API에서 제공하는 예외 클래스만으로는 다양한 종류의 예외를 표현할 수가 없다. 잔고 부족 예외와 같이 애플리케이션 서비스와 관련된 예외는 개발자가 직접 정의해서 만들어야하므로 사용자 정의 예외가 필요하다.

<br>

#### 1. 사용자 정의 예외 클래스 선언
```java
public class XXXException extends Exception { 
	public XXXException() { }
	public XXXException(String message) {  super(message);  }
}

or 

public class XXXException extends RuntimeException {
	public XXXException() { }
	public XXXException(String message) {  super(message);  }
}
```
사용자 정의 예외 클래스는 컴파일러가 체크하는(CheckedException) 일반 예외로 선언할 수도 있고, 컴파일러가 체크하지 않는(UnCheckedException) 실행 예외로 선언할 수도 있다. 

사용자 정의 예외 클래스도 필드, 생성자, 메소드 선언들을 포함할 수 있지만 대부분 생성자 선언만을 포함합니다. 생성자는 두 개를 선언하는 것이 일반적인데, 하나는 매개변수가 없는 기본 생성자 이고, 다른 하나는 예외 발생 원인 메시지를 전달하기 위해 String 타입의 매개 변수를 갖는 생성자이다.

<br>

(예시)
```java
public class BalanceInsufficientException extends Exception {
	public BalanceInsufficientException() {
	}

	public BalanceInsufficientException(String message) {
		super(message);
	}
}
```
String 타입의 매개 변수를 갖는 생성자는 상위 클래스의 생성자를 호출하여 예외 메시지를 넘겨줍니다. 예외 메시지의 용도는 catch { } 블록의 예외 처리 코드에서 이용하기 위함이다.

<br>

#### 2. 예외 발생시키기
코드에서 예외를 발생시키는 방법은 다음과 같다.
```java
throw new XXXException();

혹은

throw new XXXException("메시지");
```
하나는 기본 생성자, 또 하나는 예외 메시지를 갖는 생성자 입니다. `throw`를 이용해서 해당 예외를 던져주는(발생시키는) 역할을 한다. 

예외 발생 코드를 가지고 있는 메소드는 내부에서 try-catch 블록으로 예외를 처리할 수 있지만, **대부분은 자신을 호출한 곳에서 예외를 처리하도록 `throws` 키워드로 예외를 떠넘긴다.**
```java
public void method() throws XXXException {
	throw new XXXException("예외 메시지");
}
```
```java
try {
	method();
} catch (XXXException e) {
	// 예외 처리 코드
}
```
-> 호출한 곳에서 다음과 같이 예외 처리

<br>

#### < throw와 throws의 차이 >
- throw: 메소드 내에서 예외를 발생시키는 데 사용됨 (`throw new BalanceInsufficientException()`)
- throws: 메소드 선언부에서 사용되며, 해당 메소드가 처리하지 않은 예외를 호출자에게 전달한다는 의미를 내포하고 있음 (`public void withdraw(int money) throws BalanceInsufficientException`)

<br>

### `예외 트랜잭션 처리 방법`

트랜잭션이란 하나의 작업 단위를 뜻한다. 

예를 들어 은행에서의 '송금' 트랜잭션을 가정해보면 '송금' 트랜잭션에는 다음과 같은 작업들이 있다.

- 송금 ‘처리중’ 상태로 변경
- 송금인 계좌에 돈이 빠져나감
- 수금인 계좌에 돈이 채워짐
- 송금 ‘완료’ 상태로 변경

은행에서의 송금 프로세스 중 하나라도 실패하면 2가지 모두 취소하고 '송금' 전의 상태로 되돌려야 한다. 만약 모두 취소하지 않으면 `데이터의 정합성`(데이터들의 값이 서로 일관성 있게 일치하는 것)이 크게 흔들리게 된다. 이렇게 모두 취소하는 행위를 `롤백(Rollback)`이라고 한다.
```java
돈_송금() {
	try {
		송금_상태변경(처리중);
		송금인_계좌_출금();
		수금인_계좌_입금();
		송금_상태변경(완료);
	} catch (예외) {
		모두취소();
	}
}

송금_상태변경(status) throws 예외 {
	...
}

송금인_계좌_출금() throws 예외 {
	...
}

수금인_계좌_입금() throws 예외 {
	...
}
```

<br>

### `자동 리소스 닫기 (try-with-resourse)`
자바 7에서 새롭게 추가된 try-with-resource를 사용하면 예외 발생 여부와 상관없이 사용했던 리소스 객체(입출력, 스트림, 서버소켓, …)의 close() 메소드를 호출해서 안전하게 리소스를 닫아준다.

< 자바6 이전까지 사용했던 리소스 객체 닫기 위한 코드 >
```java
import java.io.FileInputStream;
import java.io.FileNotFoundException;
import java.io.IOException;

public class TryWithResourceExample {

	public static void main(String[] args) {
		
		FileInputStream inputStream = null;
		
		try {
			inputStream = new FileInputStream("file.txt");
			...

		} catch (FileNotFoundException e) {
			// FileNotFoundException 예외 처리 

		} finally {
			if (inputStream != null) {
				try {
					inputStream.close();

				} catch (IOException e) {
					// 예외 처리

				}
			}
		}
	}
}
```

<br>

< 자바7에서 추가된 try-with-resource구문 사용해서 리소스 닫기 >
```java
try (FileInputStream inputStream = new FileInputStream("file.txt")) {
	...

} catch (IOException e) {
	// 예외 처리

}
```
try 블록이 정상적으로 실행을 완료했거나 혹은 중간에 예외가 발생되면 자동으로 FileInputStream의 close() 메소드가 호출됩니다. try {} 에서 예외가 발생하면 우선 close()로 리소스를 닫고, catch 블록을 실행합니다.

만약 복수개의 리소스를 사용해야한다면 다음과 같이 작성할 수 있다.
```java
try (FileInputStream inputStream = new FileInputStream("file.txt");
     FileOutputStream outputStream = new FileOutputStream("file2.txt")) {
	...

} catch (IOException e) {
	// 예외 처리

}
```

<br>

#### < try-with-resource 사용 조건 >
리소스 객체는 java.lang.AutoCloseable 인터페이스를 구현하고 있어야 합니다. `AutoCloseable`에는 `close()` 메소드가 정의되어 있는데 try-with-resources는 바로 이 close() 메소드를 자동 호출한다.

<br>

```
< ch9 수업 메모 >

부모 메소드와 다른 예외를 throws 할 수 없음
- 부모 메소드와 같은 예외, 혹운 그 하위 예외는 가능
	ex) IOException / FileNotFoundException
- 단, 런타임예외는 해당 규칙에 적용 안됨

부모클래스 메소드에 들어갈 예외
- IOException
자식클래스 메소드
- FileNotFoundException
- NumberFormatException, ClassCasrException, ArithmeticException
```

<br>

## Daily Quiz
1. 예외에 대한 설명 중 틀린것은?

    1) 예외는 사용자의 잘못된 조작, 개발자의 잘못된 코딩으로 인한 프로그램 오류를 말한다.

    2) RuntimeException의 하위 예외는 컴파일러가 예외 처리 코드를 체크하지 않는다.

    3) 예외는 try-catch 블록을 사용해서 처리된다

    4) 자바 표준 예외만 프로그램에서 처리할 수 있다
```
답: 4번

자바에서는 표준 예외뿐만 아니라 사용자 정의 예외도 처리할 수 있다.
```
<br>

2. try-catch-finally 블록에 대한 설명 중 틀린 것은?

    1) try { } 블록에는 예외가 발생할 수 있는 코드를 작성한다.

    2) catch { } 블록은 try { } 블록에서 발생한 예외를 처리하는 블록이다.

    3) try { } 블록에서 return문을 사용하면 finally { } 블록은 실행되지 않는다.

    4) catch { } 블록은 예외의 종류별로 여러 개를 작성할 수 있다.
```
답: 3번

finally { } 블록은 항상 실행된다.
```
<br>

3. throws에 대한 설명으로 틀린 것은?

    1) 생성자나 메소드의 선언 끝 부분에 사용되어 내부에서 발생된 예외를 떠넘긴다.

    2) throws 뒤에는 떠넘겨야 할 예외를 쉼표(,)로 구분해서 기술한다.

    3) 모든 예외를 떠넘기기 위해 간단하게 throws Exception으로 작성할 수 있다.

    4) 새로운 예외를 발생시키기 위해 사용된다.
```
답: 4번

throws는 메소드나 생성자가 예외를 처리하지 않고 호출한 곳으로 넘길 때 사용하는 키워드이고
새로운 예외를 발생시키기 위해서는 throws가 아니라 throw 키워드를 사용한다.
```
<br>

4. throw에 대한 설명으로 틀린 것은?

    1) 예외를 최초로 발생시키는 코드이다.

    2) 예외를 호출한 곳으로 떠넘기기 위해 메소드 선언부에 작성된다.

    3) throw로 발생된 예외는 일반적으로 생성자나 메소드 선언부에 throws로 떠넘겨진다.

    4) throw 키워드 뒤에는 예외 객체 생성 코드가 온다.
```
답: 2번

예외를 호출한 곳으로 떠넘기기 위해서는 throws를 사용해야 한다. 
throw는 예외를 발생시키는 데 사용하는 키워드이다.
```
<br>

5. 다음과 같은 메소드가 있을 때 예외를 잘못 처리한 것은 무엇입니까?

    1. try { method1(); } catch(Exception e) { }

    2) void method2() throws Exception { method1() };

    3) try { method1(); } catch(Exception e) { } catch(ClassNotFoundException e) { }

    4) try { method1(); } catch(ClassNotFoundException e) { } catch(NumberFormatException e) { }
```java
public void method1() throws NumberFormatException, ClassNotFoundException { ... }
```
```
답: 3번

catch(Exception e)가 모든 예외를 포괄적으로 처리하기 때문에, catch(ClassNotFoundException e)는 절대로 실행되지 않는다.
catch(Exception e)가 가장 마지막에 와야 하며, 더 구체적인 예외부터 처리하는 것이 올바른 방법이다.
```
<br>

6. 다음 코드가 실행되었을 때 출력 결과는 무엇입니까? 
```java
public class TryCatchFinallyExample {

	public static void main(String[] args) {
		String strArray[] = {"10", "23b"};
		int value = 0;
		for (int i = 0; i < 2; i++) {
			try {
				value = Integer.parseInt(strArray[i]);
			} catch (ArrayIndexOutOfBoundsException e) {
				System.out.println("인덱스를 초과하였음");
			} catch (NumberFormatException e) {
				System.out.println("숫자로 변환할 수 없음");
			} finally {
				System.out.println(value);
			}
		}
	}

}
```
```
10
숫자로 변환할 수 없음
10
```
<br>

7. 로그인 기능을 Member 클래스의 login() 메소드에서 구현하려고 합니다. 존재하지 않는 ID를 입력했을 경우 NotExistsIdException을 발생시키고, 잘못된 패스워드를 입력했을 경우 WrongPasswordException을 발생시키려고 합니다. LoginExample의 실행 결과를 보고 빈칸을 채워보세요. 

```java
public class LoginExample {
    public static void main(String[] args) {
        try {
            login("white", "12345");
        } catch (Exception e) {
            System.out.println(e.getMessage());
        }

        try {
            login("blue", "54321");
        } catch (Exception e) {
            System.out.println(e.getMessage());
        }
    }

    public static void login(String id, String password) throws NotExistsIdException, WrongPasswordException {
        if (!id.equals("blue")) {
            throw new NotExistsIdException("아이디가 존재하지 않습니다.");
        }

        if (!password.equals("12345")) {
            throw new WrongPasswordException("패스워드가 틀립니다.");
        }
    }
}
```
```java
public WrongPasswordException(String message) {
    super(message);
}

public NotExistsIdException(String message) {
    super(message);
}
```
<LoginExample 실행결과>
```
아이디가 존재하지 않습니다.
패스워드가 틀립니다.
```