## ch9. 예외처리
### `프로그램 오류, 예외 클래스의 계층구조`
### `예외 처리 try-catch`
### `사용자 정의 예외와 예외발생`
### `예외 트랜잭션 처리 방법`
### `자동 리소스 닫기 (try-with-resourse)`

```
< ch9 수업 메모 >

부모 메소드와 다른 예외를 throws 할 수 없음
- 부모 메소드와 같은 예외, 혹운 그 하위 예외는 가능
	ex) IOException / FileNotFoundException
- 단, 런타임예외는 해당 규칙에 적용 안됨

부모클래스 메소드에 들어갈 예외
- IOException
자식클래스 메소드
- FileNotFoundException
- NumberFormatException, ClassCasrException, ArithmeticException
```

<br>

## Daily Quiz
1. 예외에 대한 설명 중 틀린것은?

    1) 예외는 사용자의 잘못된 조작, 개발자의 잘못된 코딩으로 인한 프로그램 오류를 말한다.

    2) RuntimeException의 하위 예외는 컴파일러가 예외 처리 코드를 체크하지 않는다.

    3) 예외는 try-catch 블록을 사용해서 처리된다

    4) 자바 표준 예외만 프로그램에서 처리할 수 있다
```
답: 4번

자바에서는 표준 예외뿐만 아니라 사용자 정의 예외도 처리할 수 있다.
```
<br>

2. try-catch-finally 블록에 대한 설명 중 틀린 것은?

    1) try { } 블록에는 예외가 발생할 수 있는 코드를 작성한다.

    2) catch { } 블록은 try { } 블록에서 발생한 예외를 처리하는 블록이다.

    3) try { } 블록에서 return문을 사용하면 finally { } 블록은 실행되지 않는다.

    4) catch { } 블록은 예외의 종류별로 여러 개를 작성할 수 있다.
```
답: 3번

finally { } 블록은 항상 실행된다.
```
<br>

3. throws에 대한 설명으로 틀린 것은?

    1) 생성자나 메소드의 선언 끝 부분에 사용되어 내부에서 발생된 예외를 떠넘긴다.

    2) throws 뒤에는 떠넘겨야 할 예외를 쉼표(,)로 구분해서 기술한다.

    3) 모든 예외를 떠넘기기 위해 간단하게 throws Exception으로 작성할 수 있다.

    4) 새로운 예외를 발생시키기 위해 사용된다.
```
답: 4번

throws는 메소드나 생성자가 예외를 처리하지 않고 호출한 곳으로 넘길 때 사용하는 키워드이고
새로운 예외를 발생시키기 위해서는 throws가 아니라 throw 키워드를 사용한다.
```
<br>

4. throw에 대한 설명으로 틀린 것은?

    1) 예외를 최초로 발생시키는 코드이다.

    2) 예외를 호출한 곳으로 떠넘기기 위해 메소드 선언부에 작성된다.

    3) throw로 발생된 예외는 일반적으로 생성자나 메소드 선언부에 throws로 떠넘겨진다.

    4) throw 키워드 뒤에는 예외 객체 생성 코드가 온다.
```
답: 2번

예외를 호출한 곳으로 떠넘기기 위해서는 throws를 사용해야 한다. 
throw는 예외를 발생시키는 데 사용하는 키워드이다.
```
<br>

5. 다음과 같은 메소드가 있을 때 예외를 잘못 처리한 것은 무엇입니까?

    1. try { method1(); } catch(Exception e) { }

    2) void method2() throws Exception { method1() };

    3) try { method1(); } catch(Exception e) { } catch(ClassNotFoundException e) { }

    4) try { method1(); } catch(ClassNotFoundException e) { } catch(NumberFormatException e) { }
```java
public void method1() throws NumberFormatException, ClassNotFoundException { ... }
```
```
답: 3번

catch(Exception e)가 모든 예외를 포괄적으로 처리하기 때문에, catch(ClassNotFoundException e)는 절대로 실행되지 않는다.
catch(Exception e)가 가장 마지막에 와야 하며, 더 구체적인 예외부터 처리하는 것이 올바른 방법이다.
```
<br>

6. 다음 코드가 실행되었을 때 출력 결과는 무엇입니까? 
```java
public class TryCatchFinallyExample {

	public static void main(String[] args) {
		String strArray[] = {"10", "23b"};
		int value = 0;
		for (int i = 0; i < 2; i++) {
			try {
				value = Integer.parseInt(strArray[i]);
			} catch (ArrayIndexOutOfBoundsException e) {
				System.out.println("인덱스를 초과하였음");
			} catch (NumberFormatException e) {
				System.out.println("숫자로 변환할 수 없음");
			} finally {
				System.out.println(value);
			}
		}
	}

}
```
```
10
숫자로 변환할 수 없음
10
```
<br>

7. 로그인 기능을 Member 클래스의 login() 메소드에서 구현하려고 합니다. 존재하지 않는 ID를 입력했을 경우 NotExistsIdException을 발생시키고, 잘못된 패스워드를 입력했을 경우 WrongPasswordException을 발생시키려고 합니다. LoginExample의 실행 결과를 보고 빈칸을 채워보세요. 

```java
public class LoginExample {
    public static void main(String[] args) {
        try {
            login("white", "12345");
        } catch (Exception e) {
            System.out.println(e.getMessage());
        }

        try {
            login("blue", "54321");
        } catch (Exception e) {
            System.out.println(e.getMessage());
        }
    }

    public static void login(String id, String password) throws NotExistsIdException, WrongPasswordException {
        if (!id.equals("blue")) {
            throw new NotExistsIdException("아이디가 존재하지 않습니다.");
        }

        if (!password.equals("12345")) {
            throw new WrongPasswordException("패스워드가 틀립니다.");
        }
    }
}
```
```java
public WrongPasswordException(String message) {
    super(message);
}

public NotExistsIdException(String message) {
    super(message);
}
```
<LoginExample 실행결과>
```
아이디가 존재하지 않습니다.
패스워드가 틀립니다.
```